Workbook

Sheet About
A1: CSCSCbPT Capacity Supply Curve | B1: Indiana | C1: 46255
B2: =INDEX(Keys!$C$64:$C$111,MATCH($B$1,Keys!$D$64:$D$111,0)) -> IN | C2: State code (derived)
A4: Sources: | B4: Annual capacity additions by state, plant type and vintage
B5: U.S. Energy Information Administration
B6: Form EIA-860, 2025 Early Release -- Schedule 3.1 Generator Data
B7: 2025
B8: https://www.eia.gov/electricity/data/eia860/
B9: File 3_1_Generator_Y2025_Early_Release.xlsx, sheets 'Operable' (all statuses) and 'Retired and Canceled' (status RE only). Capacity read from the 'Summer Capacity (MW)' column, NOT nameplate, because EPS capacity is net summer and seeds are absolute MW. Nationally summer = 0.939 x nameplate. Collapsed to (state, plant type, year) additions by _stage_seed_additions.py because the raw sheets are ~43k rows; see the Provenance tab for byte size, SHA-256 and drop counts. Accessed 2026-08-05.
B11: EIA plant type to EPS Electricity Source concordance
B12: Energy Innovation (this repo)
B13: outputs/build-cap-calibration/eia860_to_eps_source.csv
B14: 2026
B15: https://www.eia.gov/electricity/data/eia860/
B16: Reviewed mapping of (Technology, Prime Mover, Energy Source 1) to the 24 EPS Electricity Sources: 87 combos, 66 mapped and 21 excluded (storage, byproduct gases, waste heat, hydrogen fuel cells). Built and validated in Phase 0 of the build-cap calibration project; the stager hard-errors on any unmapped combo so a new EIA vintage cannot pass silently.
B18: Minimum power plant capacity (MPPC) -- the seed floor
B19: Energy Innovation
B20: EPS state input data, <STATE>/elec/MPPC/MPPC.csv
B21: 2026
B22: https://energyinnovation.org/energy-policy-simulator/
B23: Cross-variable paste of a different EPS input's deployed values, embedded so the MAX(seed, MPPC) floor is visible in-sheet. Byte-identical in every state (it is the national file), and the EPS.mdl comment on CSCSCbPT requires seeds to be at least as large as MPPC for the same plant type. MPPC is explicitly NOT state work -- do not edit it here.
B25: The default seed -- one value for every source and state
B26: Energy Innovation (staff decision)
B27: Seed-Capacity-Review-2026-08-21 (Robbie); Keys!uniform_seed_mw
B28: 2026
B29: https://energyinnovation.org/energy-policy-simulator/
B30: 250 MW, adopted 2026-08-21 (D-CSC-14), replacing the 24-value per-technology vector of D-CSC-13. Not measured from a data source: it is a chosen entry rate of about one utility-scale project a year, on the reasoning that a seed sets how fast a technology can START, not how big one facility is. The retired vector let plant size set deployment rate (hydrogen CC 1,940 MW/yr vs hydrogen CT 430 MW/yr, same fuel and turbines, MPPC 100 MW for both) and meant wildly different things by state (1,940 MW/yr is 233% of Vermont's fleet, 1.1% of Texas's). Caveat: this is a judgement, not an observation -- there is no primary source to verify it against, and the D-CSC-13 derivations it supersedes are preserved in docs/methodology/CSC.md and qc/csc_default_value_validation_2026-08-17.md.
A33: Notes:
A34: What this file is | B34: Per-state seed capacities for CSCSCbPT, the pre-model ramp basis in the EPS 4.0.6 capacity-expansion redesign. The seed sets BOTH the growth basis of the annual build soft cap AND the entry floor (Minimum Buildable Capacity for Plants). Because the entry floor sits outside the MIN with the hard cap, a too-large seed cannot be clipped by HCFoTC -- which is why the US values must not be copied into states.
A35: Why not the US file | B35: The US CSC-CSCSCbPT.csv encodes national annual-addition records (solar 30,000 MW, onshore wind 15,000 MW). Those are 2.3% and 1.1% of the national fleet but 3,416% and 1,708% of Vermont's. Copied verbatim into all 48 states they create a per-source build floor of 75,750 MW/yr, exceeding the entire 2025 fleet in 36 of 51 states.
A36: Seed rule (flattened 2026-08-21) | B36: Every source in every state gets the same default seed, Keys!uniform_seed_mw = 250 MW net summer, floored at MPPC: MAX(250, MPPC). The four sources the model builds at state-varying scale -- solar PV, onshore wind, natural gas combined cycle, natural gas peaker -- take MAX(state record, 250, MPPC), where the state record is its largest single-year addition 1990-2025 in net summer MW. The default is a FLOOR for those four, not a no-history fallback: Delaware's 2 MW wind record is raised to 250 rather than locking wind out at a 4 MW/yr ceiling. Keys column C says which group each source is in; nuclear is the only row where MPPC (500) binds above the default.
A37: Why only four sources look at state history | B37: A seed only does work where the model wants to build the source faster than the soft cap allows. Measured on the deployed tree, the other 20 fail that screen: 4 are prohibited by MPCbS in all 48 states (nuclear, hydro, crude oil, heavy fuel oil); 7 have never been built anywhere, so their state variation came from the analogue rather than from data (the four CCS types, SMR, both hydrogen types); 7 are not built new (hard coal, lignite, NG steam turbine, petroleum, MSW, solar thermal, biomass); and 2 are already near-uniform wherever permitted (offshore wind, geothermal). The four that remain carry 42-47 distinct values across the states and span roughly 3,400x, so one national value would cost a real ramp lag in the large states.
A38: Known limitation -- no peak-load screen | B38: decisions.md D10 calls for screening no-history seeds at 10-15% of state peak load. Not implemented: the threshold is an open staff decision (plan open question #4) and no state peak-load series exists in this repo. A largest-unit-ever proxy from EIA-860 was tested and rejected -- the retired-generator sheet omits pre-2002 retirements, so Vermont reads 65 MW (Vermont Yankee absent), biasing the screen down hardest in the small states where it would matter most. Consequence: small states can receive a one-project seed that is a large share of their fleet (Vermont NGCC 600 MW against an 878 MW fleet). Still 17x tighter than the US value it replaces.
A39: Relation to D10 | B39: D10 specifies MAX(state record, default). The 2026-08-17 build used the state record alone where a state had one, so a small record produced a small seed (Delaware wind 2 MW, a 4 MW/yr ceiling). D-CSC-14 restores the MAX, with 250 MW as the default arm, so no state is locked out of a technology by its own thin history. D10's other arm -- screening no-history seeds against state peak load -- is still not implemented; see the note below.
A40: Basis | B40: Net summer MW throughout, read from EIA-860's own Summer Capacity column. The Phase 0 panel used for other build-cap work is NAMEPLATE and is not used here: seeds are absolute MW compared against MPPC and fed to a build limit, so the basis has to match EPS. Summer runs 0.939 x nameplate nationally, which also rounds seeds down.
A41: Status | B41: INPUT FOR STAFF REVIEW -- not a deployed file and not an Energy Innovation position. Verify all numerical claims against the primary sources before any external use. Not yet gated by a paired BAU run; the first-project vector is unreviewed. See the Methodology tab for QC status and the Checks tab for live validation.

Sheet Keys
A1: category | B1: key | C1: value | D1: description
A2: window | B2: year_min | C2: 1990 | D2: First vintage year counted in the demonstrated record
A3: window | B3: year_max | C3: 2025 | D3: Last vintage year (EIA-860 2025 Early Release)
A4: convention | B4: summer_over_nameplate | C4: 0.939 | D4: National ratio of summer to nameplate additions; recorded for reference, not applied (summer is read directly from the source)
A5: qc | B5: expected_seed_cells | C5: 1152 | D5: States x sources; the Checks tab compares its populated-cell count to this
A6: qc | B6: max_seed_review_mw | C6: 50000 | D6: Above this the largest single seed gets a REVIEW verdict rather than PASS
A7: convention | B7: flag_state_specific | C7: yes | D7: Keys state_specific value marking a source whose seed is derived per state
A8: convention | B8: flag_uniform | C8: no | D8: Keys state_specific value marking a source carrying one national seed everywhere
A9: qc | B9: n_state_specific_sources | C9: 4 | D9: How many of the 24 sources keep a state derivation (staff, 2026-08-17). The Checks tab counts the Keys flags and compares to this, so adding or removing a source from LIVE_SOURCES without a deliberate decision fails the gate.
A10: qc | B10: verdict_pass | C10: PASS | D10: Verdict label used by the Checks tab
A11: qc | B11: verdict_fail | C11: FAIL | D11: Verdict label used by the Checks tab
A12: qc | B12: verdict_review | C12: REVIEW | D12: Verdict label used by the Checks tab
A13: qc | B13: verdict_reference | C13: REF | D13: Verdict label for rows that report a reference number rather than testing anything
A14: qc | B14: not_computed_here | C14: n/a -- see Methodology | D14: Placeholder for a check deliberately not computed in-workbook (basis mismatch)
A15: assumption | B15: uniform_seed_mw | C15: 250 | D15: THE default seed, MW net summer, for every source in every state (D-CSC-14, staff 2026-08-21). Edit this ONE cell and all 24 default_seed_mw rows and every seed recompute in place -- no rebuild. It is an entry rate (~one utility-scale project a year), not a plant size; the ramp supplies the scaling. MPPC still floors above it where MPPC is larger (nuclear, 500 MW).
A16: default_seed_mw | B16: hard coal | C16: =$C$15 -> 250 | D16: Flat default seed, 250 MW in every state (D-CSC-14, staff 2026-08-21). Not a plant size: a seed is an entry rate, and the ramp (2 x seed in year one, then compounding at SCGF) supplies the scaling. Replaces the D-CSC-13 per-technology vector, which set deployment rate by facility size. On Calcs this row is the floor for every state; solar PV, onshore wind, NGCC and the gas peaker raise it where their own EIA-860 record is larger. MPPC still floors above it where MPPC is bigger -- nuclear only (500 MW).
A17: default_seed_mw | B17: natural gas steam turbine | C17: =$C$15 -> 250 | D17: Flat default seed, 250 MW in every state (D-CSC-14, staff 2026-08-21). Not a plant size: a seed is an entry rate, and the ramp (2 x seed in year one, then compounding at SCGF) supplies the scaling. Replaces the D-CSC-13 per-technology vector, which set deployment rate by facility size. On Calcs this row is the floor for every state; solar PV, onshore wind, NGCC and the gas peaker raise it where their own EIA-860 record is larger. MPPC still floors above it where MPPC is bigger -- nuclear only (500 MW).
A18: default_seed_mw | B18: natural gas combined cycle | C18: =$C$15 -> 250 | D18: Flat default seed, 250 MW in every state (D-CSC-14, staff 2026-08-21). Not a plant size: a seed is an entry rate, and the ramp (2 x seed in year one, then compounding at SCGF) supplies the scaling. Replaces the D-CSC-13 per-technology vector, which set deployment rate by facility size. On Calcs this row is the floor for every state; solar PV, onshore wind, NGCC and the gas peaker raise it where their own EIA-860 record is larger. MPPC still floors above it where MPPC is bigger -- nuclear only (500 MW).
A19: default_seed_mw | B19: nuclear | C19: =$C$15 -> 250 | D19: Flat default seed, 250 MW in every state (D-CSC-14, staff 2026-08-21). Not a plant size: a seed is an entry rate, and the ramp (2 x seed in year one, then compounding at SCGF) supplies the scaling. Replaces the D-CSC-13 per-technology vector, which set deployment rate by facility size. On Calcs this row is the floor for every state; solar PV, onshore wind, NGCC and the gas peaker raise it where their own EIA-860 record is larger. MPPC still floors above it where MPPC is bigger -- nuclear only (500 MW).
A20: default_seed_mw | B20: hydro | C20: =$C$15 -> 250 | D20: Flat default seed, 250 MW in every state (D-CSC-14, staff 2026-08-21). Not a plant size: a seed is an entry rate, and the ramp (2 x seed in year one, then compounding at SCGF) supplies the scaling. Replaces the D-CSC-13 per-technology vector, which set deployment rate by facility size. On Calcs this row is the floor for every state; solar PV, onshore wind, NGCC and the gas peaker raise it where their own EIA-860 record is larger. MPPC still floors above it where MPPC is bigger -- nuclear only (500 MW).
A21: default_seed_mw | B21: onshore wind | C21: =$C$15 -> 250 | D21: Flat default seed, 250 MW in every state (D-CSC-14, staff 2026-08-21). Not a plant size: a seed is an entry rate, and the ramp (2 x seed in year one, then compounding at SCGF) supplies the scaling. Replaces the D-CSC-13 per-technology vector, which set deployment rate by facility size. On Calcs this row is the floor for every state; solar PV, onshore wind, NGCC and the gas peaker raise it where their own EIA-860 record is larger. MPPC still floors above it where MPPC is bigger -- nuclear only (500 MW).
A22: default_seed_mw | B22: solar PV | C22: =$C$15 -> 250 | D22: Flat default seed, 250 MW in every state (D-CSC-14, staff 2026-08-21). Not a plant size: a seed is an entry rate, and the ramp (2 x seed in year one, then compounding at SCGF) supplies the scaling. Replaces the D-CSC-13 per-technology vector, which set deployment rate by facility size. On Calcs this row is the floor for every state; solar PV, onshore wind, NGCC and the gas peaker raise it where their own EIA-860 record is larger. MPPC still floors above it where MPPC is bigger -- nuclear only (500 MW).
A23: default_seed_mw | B23: solar thermal | C23: =$C$15 -> 250 | D23: Flat default seed, 250 MW in every state (D-CSC-14, staff 2026-08-21). Not a plant size: a seed is an entry rate, and the ramp (2 x seed in year one, then compounding at SCGF) supplies the scaling. Replaces the D-CSC-13 per-technology vector, which set deployment rate by facility size. On Calcs this row is the floor for every state; solar PV, onshore wind, NGCC and the gas peaker raise it where their own EIA-860 record is larger. MPPC still floors above it where MPPC is bigger -- nuclear only (500 MW).
A24: default_seed_mw | B24: biomass | C24: =$C$15 -> 250 | D24: Flat default seed, 250 MW in every state (D-CSC-14, staff 2026-08-21). Not a plant size: a seed is an entry rate, and the ramp (2 x seed in year one, then compounding at SCGF) supplies the scaling. Replaces the D-CSC-13 per-technology vector, which set deployment rate by facility size. On Calcs this row is the floor for every state; solar PV, onshore wind, NGCC and the gas peaker raise it where their own EIA-860 record is larger. MPPC still floors above it where MPPC is bigger -- nuclear only (500 MW).
A25: default_seed_mw | B25: geothermal | C25: =$C$15 -> 250 | D25: Flat default seed, 250 MW in every state (D-CSC-14, staff 2026-08-21). Not a plant size: a seed is an entry rate, and the ramp (2 x seed in year one, then compounding at SCGF) supplies the scaling. Replaces the D-CSC-13 per-technology vector, which set deployment rate by facility size. On Calcs this row is the floor for every state; solar PV, onshore wind, NGCC and the gas peaker raise it where their own EIA-860 record is larger. MPPC still floors above it where MPPC is bigger -- nuclear only (500 MW).
A26: default_seed_mw | B26: petroleum | C26: =$C$15 -> 250 | D26: Flat default seed, 250 MW in every state (D-CSC-14, staff 2026-08-21). Not a plant size: a seed is an entry rate, and the ramp (2 x seed in year one, then compounding at SCGF) supplies the scaling. Replaces the D-CSC-13 per-technology vector, which set deployment rate by facility size. On Calcs this row is the floor for every state; solar PV, onshore wind, NGCC and the gas peaker raise it where their own EIA-860 record is larger. MPPC still floors above it where MPPC is bigger -- nuclear only (500 MW).
A27: default_seed_mw | B27: natural gas peaker | C27: =$C$15 -> 250 | D27: Flat default seed, 250 MW in every state (D-CSC-14, staff 2026-08-21). Not a plant size: a seed is an entry rate, and the ramp (2 x seed in year one, then compounding at SCGF) supplies the scaling. Replaces the D-CSC-13 per-technology vector, which set deployment rate by facility size. On Calcs this row is the floor for every state; solar PV, onshore wind, NGCC and the gas peaker raise it where their own EIA-860 record is larger. MPPC still floors above it where MPPC is bigger -- nuclear only (500 MW).
... A39: default_seed_mw | B39: hydrogen combined cycle | C39: =$C$15 -> 250 | D39: Flat default seed, 250 MW in every state (D-CSC-14, staff 2026-08-21). Not a plant size: a seed is an entry rate, and the ramp (2 x seed in year one, then compounding at SCGF) supplies the scaling. Replaces the D-CSC-13 per-technology vector, which set deployment rate by facility size. On Calcs this row is the floor for every state; solar PV, onshore wind, NGCC and the gas peaker raise it where their own EIA-860 record is larger. MPPC still floors above it where MPPC is bigger -- nuclear only (500 MW).
A40: state_specific | B40: hard coal | C40: no | D40: Seed is MAX(uniform_seed_mw, MPPC), identical in all 48 states
A41: state_specific | B41: natural gas steam turbine | C41: no | D41: Seed is MAX(uniform_seed_mw, MPPC), identical in all 48 states
A42: state_specific | B42: natural gas combined cycle | C42: yes | D42: Seed is MAX(this state's own EIA-860 record, uniform_seed_mw, MPPC) -- the state record can only raise it
A43: state_specific | B43: nuclear | C43: no | D43: Seed is MAX(uniform_seed_mw, MPPC), identical in all 48 states
A44: state_specific | B44: hydro | C44: no | D44: Seed is MAX(uniform_seed_mw, MPPC), identical in all 48 states
A45: state_specific | B45: onshore wind | C45: yes | D45: Seed is MAX(this state's own EIA-860 record, uniform_seed_mw, MPPC) -- the state record can only raise it
A46: state_specific | B46: solar PV | C46: yes | D46: Seed is MAX(this state's own EIA-860 record, uniform_seed_mw, MPPC) -- the state record can only raise it
A47: state_specific | B47: solar thermal | C47: no | D47: Seed is MAX(uniform_seed_mw, MPPC), identical in all 48 states
A48: state_specific | B48: biomass | C48: no | D48: Seed is MAX(uniform_seed_mw, MPPC), identical in all 48 states
A49: state_specific | B49: geothermal | C49: no | D49: Seed is MAX(uniform_seed_mw, MPPC), identical in all 48 states
A50: state_specific | B50: petroleum | C50: no | D50: Seed is MAX(uniform_seed_mw, MPPC), identical in all 48 states
A51: state_specific | B51: natural gas peaker | C51: yes | D51: Seed is MAX(this state's own EIA-860 record, uniform_seed_mw, MPPC) -- the state record can only raise it
...

Sheet Methodology
A1: CSCSCbPT Methodology
A3: Deliverable | B3: One seed capacity (MW, net summer) per state per EPS Electricity Source, written to <STATE>/elec/CSC/CSC-CSCSCbPT.csv. Row order matches eps-us exactly, including the 'solar PV' capitalisation, because EPS reads these files positionally via GET DIRECT CONSTANTS -- do not sort or re-case the rows.
A4: Tab-by-tab derivation | B4: Keys holds every constant (window years, first-project vector, the state_specific flag per source, MPPC, state codes) so no formula contains a bare string or number. EIA860_additions is the staged source, one row per (state, plant type, vintage year) with a nonzero addition, plus a LOWER() helper column for case-insensitive matching. MPPC_ref embeds the deployed MPPC vector. Calcs holds three stacked blocks: A demonstrated record, B first-project and MPPC (two national rows), C the seed. Block A carries formulas ONLY in the four state-specific columns -- a blank there means the source takes its national value straight from block B. MPCbS is not read at all (D-CSC-12). Checks validates. CSC-CSCSCbPT is the export view for the state named in About!B1.
A5: Block A -- demonstrated record | B5: MAXIFS over the staged additions: the largest single-year addition of that source in that state between Keys year_min and year_max. Returns 0 when the state has never built the source, which is what routes the cell to the first-project size. State-specific sources only.
A6: Decision D-CSC-14, 2026-08-21 -- one flat default seed of 250 MW | B6: Staff decision (Robbie, Seed-Capacity-Review-2026-08-21). Replaces the 24-value per-technology default vector of D-CSC-13 with a single number, Keys!uniform_seed_mw. Two problems it fixes. (1) The old values were plant sizes, so facility engineering set deployment rate: hydrogen combined cycle got 1,940 MW/yr and a hydrogen CT 430, same fuel and turbine vendors, with MPPC saying 100 MW for both -- and if anything big bespoke plants deploy more slowly, not faster. (2) A fixed MW/yr means different things by state: 1,940 MW/yr of hydrogen is 233% of Vermont's fleet and 1.1% of Texas's, and gas-CCS at 700 MW/yr is 24% of Delaware's, which is why DE and NH converted most of their gas fleet to CCS in a single year. The four state-specific sources also changed direction: the default is now a FLOOR under the state record rather than a fallback for states with none, so Delaware's 2 MW wind record no longer produces a 4 MW/yr ceiling. Expect small-state hydrogen, geothermal, CCS and offshore wind to fall sharply, Arkansas wind to grow at solar's expense, and Maine geothermal to drop well below the 78% of state generation it currently supplies; established wind and solar in TX, AZ, IA and AR must be UNCHANGED -- that is the regression check. No state-size term in the seed by design: pacing lives in CSCSoCECBiaSY. The D-CSC-13 derivations are not deleted -- they are preserved in docs/methodology/CSC.md and qc/csc_default_value_validation_2026-08-17.md.
A7: Decision D-CSC-12, 2026-08-17 -- MPCbS removed from the calculation | B7: The seed used to clamp at a finite MPCbS. Dropped, along with the MPCbS_ref tab. Two reasons. (1) It never bound: 0 of the 192 state-specific pairs, the closest being RI onshore wind at 1.3% of its cap -- structural, because MPCbS is a STOCK ceiling in the tens of GW while the seed is one year's addition. (2) EPS enforces it directly and later: Max Capacity Buildable This Year = MIN(MPCbS - surviving capacity, build limit), so the model intersects the build limit with the remaining headroom every year no matter what the seed says. Consequence, accepted by staff: prohibited sources now carry a populated seed (offshore wind reads 800 MW in landlocked states). The model ignores it; the methodology doc, not the sheet, is where that is explained.
A8: Decision 2026-08-05 -- basis is net summer | B8: Read from EIA-860's own Summer Capacity column rather than derating the nameplate Phase 0 panel. Seeds are absolute MW compared against MPPC and fed to a build limit, so they must be on EPS's basis. No invented derate; summer runs 0.939 x nameplate nationally, which also rounds seeds down per D10's risk asymmetry.
A9: Decision D-CSC-11, 2026-08-17 -- uniform seeds outside the four live sources | B9: Staff decision. Replaces the analogue map (retired) and the per-state derivation for 20 of 24 sources. Rationale on the About tab. The uniform value is the national first-project size floored at MPPC, which is what the previous build already fell back to for any state with no history. SUPERSEDED IN PART by D-CSC-14: the uniform GROUPING stands, but the value is now one flat 250 MW rather than a per-technology vector. Some uniform values rise against what was deployed (biomass 27 -> 50 MW at the median, nuclear 500 -> 1,100, hydro 1 -> 50): safe, because the seed floors the build LIMIT, not the build. A 50 MW floor does not make a state build 50 MW of biomass unless the economics already want it. The rows where a large uniform floor WOULD be dangerous in a small state -- nuclear, hydro, offshore wind, hard coal, lignite -- are blocked by MPCbS = 0 in every state that is not already building them.
A10: Retired 2026-08-17 -- the analogue map | B10: Four CCS types inherited their unabated parent, hydrogen CT the gas peaker, hydrogen CC the NGCC. Its only job was to give never-built types a state-varying seed; all those sources are now uniform, so nothing consumed it. The reasoning is preserved in docs/methodology/CSC.md sections 8 and 9 -- read it before reintroducing a state derivation for any never-built source.
A11: Known caveat -- no peak-load screen | B11: See the About tab. D10 wants 10-15% of state peak load for no-history sources; the threshold is an open staff decision and no peak series exists in this repo. The largest-unit-ever proxy was tested and rejected because EIA-860's retired sheet omits pre-2002 retirements (Vermont reads 65 MW with Vermont Yankee absent). Small states can therefore carry a one-project seed that is a large share of their fleet.
A12: Known caveat -- retired-sheet coverage | B12: Additions are unaffected (they come from operating years, which are complete), but any comparison of a seed to a historical FLEET level inherits Phase 0's caveat that pre-2002 retirements are missing.
A13: QC status | B13: Checks tab is live in-workbook. An independent Python replica (qc/csc_replica_qc.py) re-derives every cell from the staged source and the published rule rather than from this builder. NOT yet gated by a paired BAU run -- per the CRpUNL precedent that gate is required before deploy. The 250 MW default is a staff judgement, not a measured quantity; the regression check that matters is that established wind and solar in TX, AZ, IA and AR are unchanged from the 2026-08-17 deployed values.
A14: Not final | B14: Input for staff review. Not an Energy Innovation position. Verify numbers against primary sources before external use.

Sheet Provenance
A1: Staging provenance -- EIA-860 additions table
A3: CSCSCbPT seed staging provenance
A5: - Raw file: sources/raw/eia860_2025er/3_1_Generator_Y2025_Early_Release.xlsx
A6: - Bytes: 11,086,120
A7: - SHA-256: 0513a75bba11546b6a6c63118a3809e9c3097b63b6ecd2c3a6c909e4f4992eca
A8: - Sheets read: Operable (all statuses), Retired and Canceled (status RE only)
A9: - Generators contributing an addition in 1990-2025: 20,778
A10: - Output rows (nonzero (state, source, year) additions): 3,562
A11: - Capacity basis: Summer Capacity (MW) (EIA-860 col R) to match EPS net summer
A12: - Total staged additions: 793,276 MW summer vs 845,078 MW nameplate (summer = 0.939 x nameplate)
A14: Drops / fallbacks
A16: - missing operating year or state: 2 generators, 2 MW
A17: - summer blank -> nameplate used: 166 generators, 12,934 MW

Sheet EIA860_additions
A1: state | B1: eps_source | C1: year | D1: mw_added_summer | E1: mw_added_nameplate | F1: source_key
A2: AK | B2: biomass | C2: 2012 | D2: 5.6 | E2: 9.2 | F2: =LOWER($B2) -> biomass
A3: AK | B3: biomass | C3: 2013 | D3: 1.4 | E3: 2.3 | F3: =LOWER($B3) -> biomass
A4: AK | B4: hard coal | C4: 2020 | D4: 17 | E4: 17 | F4: =LOWER($B4) -> hard coal
A5: AK | B5: hard coal | C5: 2025 | D5: 9 | E5: 10 | F5: =LOWER($B5) -> hard coal
A6: AK | B6: hydro | C6: 1990 | D6: 31 | E6: 31 | F6: =LOWER($B6) -> hydro
A7: AK | B7: hydro | C7: 1991 | D7: 127 | E7: 127.2 | F7: =LOWER($B7) -> hydro
A8: AK | B8: hydro | C8: 1995 | D8: 4.8 | E8: 5.3 | F8: =LOWER($B8) -> hydro
A9: AK | B9: hydro | C9: 1997 | D9: 4 | E9: 4 | F9: =LOWER($B9) -> hydro
A10: AK | B10: hydro | C10: 1998 | D10: 0.8 | E10: 0.8 | F10: =LOWER($B10) -> hydro
A11: AK | B11: hydro | C11: 2001 | D11: 5.6 | E11: 6 | F11: =LOWER($B11) -> hydro
A12: AK | B12: hydro | C12: 2005 | D12: 1.9 | E12: 2 | F12: =LOWER($B12) -> hydro
A13: AK | B13: hydro | C13: 2008 | D13: 3 | E13: 3 | F13: =LOWER($B13) -> hydro
... A3563: WY | B3563: solar pv | C3563: 2024 | D3563: 150 | E3563: 150 | F3563: =LOWER($B3563) -> solar pv

Sheet MPPC_ref
A1: MPPC Minimum Power Plant Capacity -- one national vector. Builder verified all 48 deployed state MPPC.csv files identical before embedding. EDITABLE: the Calcs seed floor reads row 3 live.
A2: value (MW) | B2: hard coal | C2: natural gas steam turbine | D2: natural gas combined cycle | E2: nuclear | F2: hydro | G2: onshore wind | H2: solar PV | I2: solar thermal | J2: biomass | K2: geothermal | L2: petroleum | M2: natural gas peaker | N2: lignite | O2: offshore wind | P2: crude oil | Q2: heavy or residual fuel oil | R2: municipal solid waste | S2: hard coal w CCS | T2: natural gas combined cycle w CCS | U2: biomass w CCS | V2: lignite w CCS | W2: small modular reactor | X2: hydrogen combustion turbine | Y2: hydrogen combined cycle
B3: 50 | C3: 50 | D3: 50 | E3: 500 | F3: 1 | G3: 1 | H3: 1 | I3: 50 | J3: 1 | K3: 50 | L3: 50 | M3: 50 | N3: 50 | O3: 1 | P3: 50 | Q3: 50 | R3: 10 | S3: 100 | T3: 100 | U3: 10 | V3: 100 | W3: 100 | X3: 100 | Y3: 100

Sheet US_CSC_source
A1: CSC-CSCPH.csv -- eps-us/InputData/elec/CSC/CSC-CSCPH.csv
A2: Procurement headroom. Structural constant 2.0 everywhere (decisions.md D12), not regional data.
A3: Multiple of annual build limit available for procurement
A4: Headroom | B4: 2
A7: CSC-CSCP.csv -- eps-us/InputData/elec/CSC/CSC-CSCP.csv
A8: Capacity supply curve shape parameters. National curve geometry; no state basis.
A9: parameters | B9: value
A10: saturation | B10: 0.2
A11: scale parameter | B11: 0.6
A12: shape parameter | B12: 3
A13: location parameter | B13: 0.5
A14: cutoff parameter | B14: 30000
A17: CSC-CSCSoCECBiaSY.csv -- eps-us/InputData/elec/CSC/CSC-CSCSoCECBiaSY.csv
A18: Share of cost-effective capacity built in a single year, by source and year. Already byte-identical to the US file in every deployed state.
A19: Time (Year) | B19: 2024 | C19: 2025 | D19: 2026 | E19: 2027 | F19: 2028 | G19: 2029 | H19: 2030 | I19: 2031 | J19: 2032 | K19: 2033 | L19: 2034 | M19: 2035 | N19: 2036 | O19: 2037 | P19: 2038 | Q19: 2039 | R19: 2040 | S19: 2041 | T19: 2042 | U19: 2043 | V19: 2044 | W19: 2045 | X19: 2046 | Y19: 2047 | Z19: 2048 | AA19: 2049 | AB19: 2050
A20: hard coal es | B20: 1 | C20: 1 | D20: 1 | E20: 1 | F20: 1 | G20: 1 | H20: 1 | I20: 1 | J20: 1 | K20: 1 | L20: 1 | M20: 1 | N20: 1 | O20: 1 | P20: 1 | Q20: 1 | R20: 1 | S20: 1 | T20: 1 | U20: 1 | V20: 1 | W20: 1 | X20: 1 | Y20: 1 | Z20: 1 | AA20: 1 | AB20: 1
A21: natural gas steam turbine es | B21: 1 | C21: 1 | D21: 1 | E21: 1 | F21: 1 | G21: 1 | H21: 1 | I21: 1 | J21: 1 | K21: 1 | L21: 1 | M21: 1 | N21: 1 | O21: 1 | P21: 1 | Q21: 1 | R21: 1 | S21: 1 | T21: 1 | U21: 1 | V21: 1 | W21: 1 | X21: 1 | Y21: 1 | Z21: 1 | AA21: 1 | AB21: 1
A22: natural gas combined cycle es | B22: 1 | C22: 1 | D22: 1 | E22: 1 | F22: 1 | G22: 1 | H22: 1 | I22: 1 | J22: 1 | K22: 1 | L22: 1 | M22: 1 | N22: 1 | O22: 1 | P22: 1 | Q22: 1 | R22: 1 | S22: 1 | T22: 1 | U22: 1 | V22: 1 | W22: 1 | X22: 1 | Y22: 1 | Z22: 1 | AA22: 1 | AB22: 1
A23: nuclear es | B23: 1 | C23: 1 | D23: 1 | E23: 1 | F23: 1 | G23: 1 | H23: 1 | I23: 1 | J23: 1 | K23: 1 | L23: 1 | M23: 1 | N23: 1 | O23: 1 | P23: 1 | Q23: 1 | R23: 1 | S23: 1 | T23: 1 | U23: 1 | V23: 1 | W23: 1 | X23: 1 | Y23: 1 | Z23: 1 | AA23: 1 | AB23: 1
A24: hydro es | B24: 1 | C24: 1 | D24: 1 | E24: 1 | F24: 1 | G24: 1 | H24: 1 | I24: 1 | J24: 1 | K24: 1 | L24: 1 | M24: 1 | N24: 1 | O24: 1 | P24: 1 | Q24: 1 | R24: 1 | S24: 1 | T24: 1 | U24: 1 | V24: 1 | W24: 1 | X24: 1 | Y24: 1 | Z24: 1 | AA24: 1 | AB24: 1
A25: onshore wind es | B25: 0.8 | C25: 0.1 | D25: 0.1 | E25: 0.1 | F25: 0.1 | G25: 0.1 | H25: 0.33333333 | I25: 0.56666667 | J25: 0.8 | K25: 0.8 | L25: 0.8 | M25: 0.8 | N25: 0.8 | O25: 0.8 | P25: 0.8 | Q25: 0.8 | R25: 0.8 | S25: 0.8 | T25: 0.8 | U25: 0.8 | V25: 0.8 | W25: 0.8 | X25: 0.8 | Y25: 0.8 | Z25: 0.8 | AA25: 0.8 | AB25: 0.8
A26: solar PV es | B26: 1 | C26: 1 | D26: 1 | E26: 1 | F26: 1 | G26: 1 | H26: 1 | I26: 1 | J26: 1 | K26: 1 | L26: 1 | M26: 1 | N26: 1 | O26: 1 | P26: 1 | Q26: 1 | R26: 1 | S26: 1 | T26: 1 | U26: 1 | V26: 1 | W26: 1 | X26: 1 | Y26: 1 | Z26: 1 | AA26: 1 | AB26: 1
A27: solar thermal es | B27: 1 | C27: 1 | D27: 1 | E27: 1 | F27: 1 | G27: 1 | H27: 1 | I27: 1 | J27: 1 | K27: 1 | L27: 1 | M27: 1 | N27: 1 | O27: 1 | P27: 1 | Q27: 1 | R27: 1 | S27: 1 | T27: 1 | U27: 1 | V27: 1 | W27: 1 | X27: 1 | Y27: 1 | Z27: 1 | AA27: 1 | AB27: 1
A28: biomass es | B28: 1 | C28: 1 | D28: 1 | E28: 1 | F28: 1 | G28: 1 | H28: 1 | I28: 1 | J28: 1 | K28: 1 | L28: 1 | M28: 1 | N28: 1 | O28: 1 | P28: 1 | Q28: 1 | R28: 1 | S28: 1 | T28: 1 | U28: 1 | V28: 1 | W28: 1 | X28: 1 | Y28: 1 | Z28: 1 | AA28: 1 | AB28: 1
A29: geothermal es | B29: 1 | C29: 1 | D29: 1 | E29: 1 | F29: 1 | G29: 1 | H29: 1 | I29: 1 | J29: 1 | K29: 1 | L29: 1 | M29: 1 | N29: 1 | O29: 1 | P29: 1 | Q29: 1 | R29: 1 | S29: 1 | T29: 1 | U29: 1 | V29: 1 | W29: 1 | X29: 1 | Y29: 1 | Z29: 1 | AA29: 1 | AB29: 1
A30: petroleum es | B30: 1 | C30: 1 | D30: 1 | E30: 1 | F30: 1 | G30: 1 | H30: 1 | I30: 1 | J30: 1 | K30: 1 | L30: 1 | M30: 1 | N30: 1 | O30: 1 | P30: 1 | Q30: 1 | R30: 1 | S30: 1 | T30: 1 | U30: 1 | V30: 1 | W30: 1 | X30: 1 | Y30: 1 | Z30: 1 | AA30: 1 | AB30: 1
... A43: hydrogen combined cycle es | B43: 1 | C43: 1 | D43: 1 | E43: 1 | F43: 1 | G43: 1 | H43: 1 | I43: 1 | J43: 1 | K43: 1 | L43: 1 | M43: 1 | N43: 1 | O43: 1 | P43: 1 | Q43: 1 | R43: 1 | S43: 1 | T43: 1 | U43: 1 | V43: 1 | W43: 1 | X43: 1 | Y43: 1 | Z43: 1 | AA43: 1 | AB43: 1

Sheet Calcs
A1: A. Demonstrated record -- largest single-year addition, net summer MW (MAXIFS over EIA860_additions). State-specific sources only.
A2: state | B2: hard coal | C2: natural gas steam turbine | D2: natural gas combined cycle | E2: nuclear | F2: hydro | G2: onshore wind | H2: solar PV | I2: solar thermal | J2: biomass | K2: geothermal | L2: petroleum | M2: natural gas peaker | N2: lignite | O2: offshore wind | P2: crude oil | Q2: heavy or residual fuel oil | R2: municipal solid waste | S2: hard coal w CCS | T2: natural gas combined cycle w CCS | U2: biomass w CCS | V2: lignite w CCS | W2: small modular reactor | X2: hydrogen combustion turbine | Y2: hydrogen combined cycle
A3: source_key (helper) | B3: =LOWER(B$2) -> hard coal | C3: =LOWER(C$2) -> natural gas steam turbine | D3: =LOWER(D$2) -> natural gas combined cycle | E3: =LOWER(E$2) -> nuclear | F3: =LOWER(F$2) -> hydro | G3: =LOWER(G$2) -> onshore wind | H3: =LOWER(H$2) -> solar pv | I3: =LOWER(I$2) -> solar thermal | ... Y3: =LOWER(Y$2) -> hydrogen combined cycle
A4: AL | D4: =_xlfn.MAXIFS(EIA860_additions!$D$2:$D$3563,EIA860_additions!$A$2:$A$3563,$A4,EIA860_additions!$F$2:$F$3563,D$3) -> 3221.6 | G4: =_xlfn.MAXIFS(EIA860_additions!$D$2:$D$3563,EIA860_additions!$A$2:$A$3563,$A4,EIA860_additions!$F$2:$F$3563,G$3) -> 0 | H4: =_xlfn.MAXIFS(EIA860_additions!$D$2:$D$3563,EIA860_additions!$A$2:$A$3563,$A4,EIA860_additions!$F$2:$F$3563,H$3) -> 227 | M4: =_xlfn.MAXIFS(EIA860_additions!$D$2:$D$3563,EIA860_additions!$A$2:$A$3563,$A4,EIA860_additions!$F$2:$F$3563,M$3) -> 704
A5: AR | D5: =_xlfn.MAXIFS(EIA860_additions!$D$2:$D$3563,EIA860_additions!$A$2:$A$3563,$A5,EIA860_additions!$F$2:$F$3563,D$3) -> 3456.6 | G5: =_xlfn.MAXIFS(EIA860_additions!$D$2:$D$3563,EIA860_additions!$A$2:$A$3563,$A5,EIA860_additions!$F$2:$F$3563,G$3) -> 135 | H5: =_xlfn.MAXIFS(EIA860_additions!$D$2:$D$3563,EIA860_additions!$A$2:$A$3563,$A5,EIA860_additions!$F$2:$F$3563,H$3) -> 945.66 | M5: =_xlfn.MAXIFS(EIA860_additions!$D$2:$D$3563,EIA860_additions!$A$2:$A$3563,$A5,EIA860_additions!$F$2:$F$3563,M$3) -> 340
A6: AZ | D6: =_xlfn.MAXIFS(EIA860_additions!$D$2:$D$3563,EIA860_additions!$A$2:$A$3563,$A6,EIA860_additions!$F$2:$F$3563,D$3) -> 3996 | G6: =_xlfn.MAXIFS(EIA860_additions!$D$2:$D$3563,EIA860_additions!$A$2:$A$3563,$A6,EIA860_additions!$F$2:$F$3563,G$3) -> 379 | H6: =_xlfn.MAXIFS(EIA860_additions!$D$2:$D$3563,EIA860_additions!$A$2:$A$3563,$A6,EIA860_additions!$F$2:$F$3563,H$3) -> 1532.3 | M6: =_xlfn.MAXIFS(EIA860_additions!$D$2:$D$3563,EIA860_additions!$A$2:$A$3563,$A6,EIA860_additions!$F$2:$F$3563,M$3) -> 613.9
A7: CA | D7: =_xlfn.MAXIFS(EIA860_additions!$D$2:$D$3563,EIA860_additions!$A$2:$A$3563,$A7,EIA860_additions!$F$2:$F$3563,D$3) -> 4152.2 | G7: =_xlfn.MAXIFS(EIA860_additions!$D$2:$D$3563,EIA860_additions!$A$2:$A$3563,$A7,EIA860_additions!$F$2:$F$3563,G$3) -> 1954.5 | H7: =_xlfn.MAXIFS(EIA860_additions!$D$2:$D$3563,EIA860_additions!$A$2:$A$3563,$A7,EIA860_additions!$F$2:$F$3563,H$3) -> 2765.5 | M7: =_xlfn.MAXIFS(EIA860_additions!$D$2:$D$3563,EIA860_additions!$A$2:$A$3563,$A7,EIA860_additions!$F$2:$F$3563,M$3) -> 2737.4
A8: CO | D8: =_xlfn.MAXIFS(EIA860_additions!$D$2:$D$3563,EIA860_additions!$A$2:$A$3563,$A8,EIA860_additions!$F$2:$F$3563,D$3) -> 682.4 | G8: =_xlfn.MAXIFS(EIA860_additions!$D$2:$D$3563,EIA860_additions!$A$2:$A$3563,$A8,EIA860_additions!$F$2:$F$3563,G$3) -> 969.1 | H8: =_xlfn.MAXIFS(EIA860_additions!$D$2:$D$3563,EIA860_additions!$A$2:$A$3563,$A8,EIA860_additions!$F$2:$F$3563,H$3) -> 888.12 | M8: =_xlfn.MAXIFS(EIA860_additions!$D$2:$D$3563,EIA860_additions!$A$2:$A$3563,$A8,EIA860_additions!$F$2:$F$3563,M$3) -> 573.4
A9: CT | D9: =_xlfn.MAXIFS(EIA860_additions!$D$2:$D$3563,EIA860_additions!$A$2:$A$3563,$A9,EIA860_additions!$F$2:$F$3563,D$3) -> 828.8 | G9: =_xlfn.MAXIFS(EIA860_additions!$D$2:$D$3563,EIA860_additions!$A$2:$A$3563,$A9,EIA860_additions!$F$2:$F$3563,G$3) -> 5 | H9: =_xlfn.MAXIFS(EIA860_additions!$D$2:$D$3563,EIA860_additions!$A$2:$A$3563,$A9,EIA860_additions!$F$2:$F$3563,H$3) -> 167.9 | M9: =_xlfn.MAXIFS(EIA860_additions!$D$2:$D$3563,EIA860_additions!$A$2:$A$3563,$A9,EIA860_additions!$F$2:$F$3563,M$3) -> 227.84
A10: DE | D10: =_xlfn.MAXIFS(EIA860_additions!$D$2:$D$3563,EIA860_additions!$A$2:$A$3563,$A10,EIA860_additions!$F$2:$F$3563,D$3) -> 416 | G10: =_xlfn.MAXIFS(EIA860_additions!$D$2:$D$3563,EIA860_additions!$A$2:$A$3563,$A10,EIA860_additions!$F$2:$F$3563,G$3) -> 2 | H10: =_xlfn.MAXIFS(EIA860_additions!$D$2:$D$3563,EIA860_additions!$A$2:$A$3563,$A10,EIA860_additions!$F$2:$F$3563,H$3) -> 51.5 | M10: =_xlfn.MAXIFS(EIA860_additions!$D$2:$D$3563,EIA860_additions!$A$2:$A$3563,$A10,EIA860_additions!$F$2:$F$3563,M$3) -> 130
A11: FL | D11: =_xlfn.MAXIFS(EIA860_additions!$D$2:$D$3563,EIA860_additions!$A$2:$A$3563,$A11,EIA860_additions!$F$2:$F$3563,D$3) -> 3684 | G11: =_xlfn.MAXIFS(EIA860_additions!$D$2:$D$3563,EIA860_additions!$A$2:$A$3563,$A11,EIA860_additions!$F$2:$F$3563,G$3) -> 0 | H11: =_xlfn.MAXIFS(EIA860_additions!$D$2:$D$3563,EIA860_additions!$A$2:$A$3563,$A11,EIA860_additions!$F$2:$F$3563,H$3) -> 3154 | M11: =_xlfn.MAXIFS(EIA860_additions!$D$2:$D$3563,EIA860_additions!$A$2:$A$3563,$A11,EIA860_additions!$F$2:$F$3563,M$3) -> 1934.65
A12: GA | D12: =_xlfn.MAXIFS(EIA860_additions!$D$2:$D$3563,EIA860_additions!$A$2:$A$3563,$A12,EIA860_additions!$F$2:$F$3563,D$3) -> 2537.8 | G12: =_xlfn.MAXIFS(EIA860_additions!$D$2:$D$3563,EIA860_additions!$A$2:$A$3563,$A12,EIA860_additions!$F$2:$F$3563,G$3) -> 0 | H12: =_xlfn.MAXIFS(EIA860_additions!$D$2:$D$3563,EIA860_additions!$A$2:$A$3563,$A12,EIA860_additions!$F$2:$F$3563,H$3) -> 870.1 | M12: =_xlfn.MAXIFS(EIA860_additions!$D$2:$D$3563,EIA860_additions!$A$2:$A$3563,$A12,EIA860_additions!$F$2:$F$3563,M$3) -> 2284.6
A13: IA | D13: =_xlfn.MAXIFS(EIA860_additions!$D$2:$D$3563,EIA860_additions!$A$2:$A$3563,$A13,EIA860_additions!$F$2:$F$3563,D$3) -> 768.4 | G13: =_xlfn.MAXIFS(EIA860_additions!$D$2:$D$3563,EIA860_additions!$A$2:$A$3563,$A13,EIA860_additions!$F$2:$F$3563,G$3) -> 1495.9 | H13: =_xlfn.MAXIFS(EIA860_additions!$D$2:$D$3563,EIA860_additions!$A$2:$A$3563,$A13,EIA860_additions!$F$2:$F$3563,H$3) -> 416.7 | M13: =_xlfn.MAXIFS(EIA860_additions!$D$2:$D$3563,EIA860_additions!$A$2:$A$3563,$A13,EIA860_additions!$F$2:$F$3563,M$3) -> 180.5
A14: ID | D14: =_xlfn.MAXIFS(EIA860_additions!$D$2:$D$3563,EIA860_additions!$A$2:$A$3563,$A14,EIA860_additions!$F$2:$F$3563,D$3) -> 303.32 | G14: =_xlfn.MAXIFS(EIA860_additions!$D$2:$D$3563,EIA860_additions!$A$2:$A$3563,$A14,EIA860_additions!$F$2:$F$3563,G$3) -> 351.3 | H14: =_xlfn.MAXIFS(EIA860_additions!$D$2:$D$3563,EIA860_additions!$A$2:$A$3563,$A14,EIA860_additions!$F$2:$F$3563,H$3) -> 200 | M14: =_xlfn.MAXIFS(EIA860_additions!$D$2:$D$3563,EIA860_additions!$A$2:$A$3563,$A14,EIA860_additions!$F$2:$F$3563,M$3) -> 185.12
A15: IL | D15: =_xlfn.MAXIFS(EIA860_additions!$D$2:$D$3563,EIA860_additions!$A$2:$A$3563,$A15,EIA860_additions!$F$2:$F$3563,D$3) -> 1742.2 | G15: =_xlfn.MAXIFS(EIA860_additions!$D$2:$D$3563,EIA860_additions!$A$2:$A$3563,$A15,EIA860_additions!$F$2:$F$3563,G$3) -> 1098 | H15: =_xlfn.MAXIFS(EIA860_additions!$D$2:$D$3563,EIA860_additions!$A$2:$A$3563,$A15,EIA860_additions!$F$2:$F$3563,H$3) -> 1746 | M15: =_xlfn.MAXIFS(EIA860_additions!$D$2:$D$3563,EIA860_additions!$A$2:$A$3563,$A15,EIA860_additions!$F$2:$F$3563,M$3) -> 3017.6
... A51: WY | D51: =_xlfn.MAXIFS(EIA860_additions!$D$2:$D$3563,EIA860_additions!$A$2:$A$3563,$A51,EIA860_additions!$F$2:$F$3563,D$3) -> 94 | G51: =_xlfn.MAXIFS(EIA860_additions!$D$2:$D$3563,EIA860_additions!$A$2:$A$3563,$A51,EIA860_additions!$F$2:$F$3563,G$3) -> 1061.2 | H51: =_xlfn.MAXIFS(EIA860_additions!$D$2:$D$3563,EIA860_additions!$A$2:$A$3563,$A51,EIA860_additions!$F$2:$F$3563,H$3) -> 150 | M51: =_xlfn.MAXIFS(EIA860_additions!$D$2:$D$3563,EIA860_additions!$A$2:$A$3563,$A51,EIA860_additions!$F$2:$F$3563,M$3) -> 100.5
A54: B. National rows -- first-project size (Keys) and MPPC floor (MPPC_ref, live). These two rows ARE the seed for the 20 sources that are not state-specific.
A55: state | B55: hard coal | C55: natural gas steam turbine | D55: natural gas combined cycle | E55: nuclear | F55: hydro | G55: onshore wind | H55: solar PV | I55: solar thermal | J55: biomass | K55: geothermal | L55: petroleum | M55: natural gas peaker | N55: lignite | O55: offshore wind | P55: crude oil | Q55: heavy or residual fuel oil | R55: municipal solid waste | S55: hard coal w CCS | T55: natural gas combined cycle w CCS | U55: biomass w CCS | V55: lignite w CCS | W55: small modular reactor | X55: hydrogen combustion turbine | Y55: hydrogen combined cycle
A56: source_key (helper) | B56: =LOWER(B$55) -> hard coal | C56: =LOWER(C$55) -> natural gas steam turbine | D56: =LOWER(D$55) -> natural gas combined cycle | E56: =LOWER(E$55) -> nuclear | F56: =LOWER(F$55) -> hydro | G56: =LOWER(G$55) -> onshore wind | H56: =LOWER(H$55) -> solar pv | I56: =LOWER(I$55) -> solar thermal | ... Y56: =LOWER(Y$55) -> hydrogen combined cycle
A57: first_project_mw | B57: =INDEX(Keys!$C$16:$C$39,MATCH(B$55,Keys!$B$16:$B$39,0)) -> 250 | C57: =INDEX(Keys!$C$16:$C$39,MATCH(C$55,Keys!$B$16:$B$39,0)) -> 250 | D57: =INDEX(Keys!$C$16:$C$39,MATCH(D$55,Keys!$B$16:$B$39,0)) -> 250 | E57: =INDEX(Keys!$C$16:$C$39,MATCH(E$55,Keys!$B$16:$B$39,0)) -> 250 | F57: =INDEX(Keys!$C$16:$C$39,MATCH(F$55,Keys!$B$16:$B$39,0)) -> 250 | G57: =INDEX(Keys!$C$16:$C$39,MATCH(G$55,Keys!$B$16:$B$39,0)) -> 250 | H57: =INDEX(Keys!$C$16:$C$39,MATCH(H$55,Keys!$B$16:$B$39,0)) -> 250 | I57: =INDEX(Keys!$C$16:$C$39,MATCH(I$55,Keys!$B$16:$B$39,0)) -> 250 | ... Y57: =INDEX(Keys!$C$16:$C$39,MATCH(Y$55,Keys!$B$16:$B$39,0)) -> 250
A58: mppc_mw (from MPPC_ref) | B58: =INDEX(MPPC_ref!$B$3:$Y$3,MATCH(B$55,MPPC_ref!$B$2:$Y$2,0)) -> 50 | C58: =INDEX(MPPC_ref!$B$3:$Y$3,MATCH(C$55,MPPC_ref!$B$2:$Y$2,0)) -> 50 | D58: =INDEX(MPPC_ref!$B$3:$Y$3,MATCH(D$55,MPPC_ref!$B$2:$Y$2,0)) -> 50 | E58: =INDEX(MPPC_ref!$B$3:$Y$3,MATCH(E$55,MPPC_ref!$B$2:$Y$2,0)) -> 500 | F58: =INDEX(MPPC_ref!$B$3:$Y$3,MATCH(F$55,MPPC_ref!$B$2:$Y$2,0)) -> 1 | G58: =INDEX(MPPC_ref!$B$3:$Y$3,MATCH(G$55,MPPC_ref!$B$2:$Y$2,0)) -> 1 | H58: =INDEX(MPPC_ref!$B$3:$Y$3,MATCH(H$55,MPPC_ref!$B$2:$Y$2,0)) -> 1 | I58: =INDEX(MPPC_ref!$B$3:$Y$3,MATCH(I$55,MPPC_ref!$B$2:$Y$2,0)) -> 50 | ... Y58: =INDEX(MPPC_ref!$B$3:$Y$3,MATCH(Y$55,MPPC_ref!$B$2:$Y$2,0)) -> 100
A61: C. SEED (MW, net summer) -- the deliverable
A62: state | B62: hard coal | C62: natural gas steam turbine | D62: natural gas combined cycle | E62: nuclear | F62: hydro | G62: onshore wind | H62: solar PV | I62: solar thermal | J62: biomass | K62: geothermal | L62: petroleum | M62: natural gas peaker | N62: lignite | O62: offshore wind | P62: crude oil | Q62: heavy or residual fuel oil | R62: municipal solid waste | S62: hard coal w CCS | T62: natural gas combined cycle w CCS | U62: biomass w CCS | V62: lignite w CCS | W62: small modular reactor | X62: hydrogen combustion turbine | Y62: hydrogen combined cycle
A63: source_key (helper) | B63: =LOWER(B$62) -> hard coal | C63: =LOWER(C$62) -> natural gas steam turbine | D63: =LOWER(D$62) -> natural gas combined cycle | E63: =LOWER(E$62) -> nuclear | F63: =LOWER(F$62) -> hydro | G63: =LOWER(G$62) -> onshore wind | H63: =LOWER(H$62) -> solar pv | I63: =LOWER(I$62) -> solar thermal | ... Y63: =LOWER(Y$62) -> hydrogen combined cycle
A64: AL | B64: =MAX(B$57,B$58) -> 250 | C64: =MAX(C$57,C$58) -> 250 | D64: =MAX(D4,D$57,D$58) -> 3221.6 | E64: =MAX(E$57,E$58) -> 500 | F64: =MAX(F$57,F$58) -> 250 | G64: =MAX(G4,G$57,G$58) -> 250 | H64: =MAX(H4,H$57,H$58) -> 250 | I64: =MAX(I$57,I$58) -> 250 | J64: =MAX(J$57,J$58) -> 250 | K64: =MAX(K$57,K$58) -> 250 | L64: =MAX(L$57,L$58) -> 250 | M64: =MAX(M4,M$57,M$58) -> 704 | N64: =MAX(N$57,N$58) -> 250 | O64: =MAX(O$57,O$58) -> 250 | P64: =MAX(P$57,P$58) -> 250 | Q64: =MAX(Q$57,Q$58) -> 250 | R64: =MAX(R$57,R$58) -> 250 | S64: =MAX(S$57,S$58) -> 250 | T64: =MAX(T$57,T$58) -> 250 | U64: =MAX(U$57,U$58) -> 250 | ... Y64: =MAX(Y$57,Y$58) -> 250
A65: AR | B65: =MAX(B$57,B$58) -> 250 | C65: =MAX(C$57,C$58) -> 250 | D65: =MAX(D5,D$57,D$58) -> 3456.6 | E65: =MAX(E$57,E$58) -> 500 | F65: =MAX(F$57,F$58) -> 250 | G65: =MAX(G5,G$57,G$58) -> 250 | H65: =MAX(H5,H$57,H$58) -> 945.66 | I65: =MAX(I$57,I$58) -> 250 | J65: =MAX(J$57,J$58) -> 250 | K65: =MAX(K$57,K$58) -> 250 | L65: =MAX(L$57,L$58) -> 250 | M65: =MAX(M5,M$57,M$58) -> 340 | N65: =MAX(N$57,N$58) -> 250 | O65: =MAX(O$57,O$58) -> 250 | P65: =MAX(P$57,P$58) -> 250 | Q65: =MAX(Q$57,Q$58) -> 250 | R65: =MAX(R$57,R$58) -> 250 | S65: =MAX(S$57,S$58) -> 250 | T65: =MAX(T$57,T$58) -> 250 | U65: =MAX(U$57,U$58) -> 250 | ... Y65: =MAX(Y$57,Y$58) -> 250
A66: AZ | B66: =MAX(B$57,B$58) -> 250 | C66: =MAX(C$57,C$58) -> 250 | D66: =MAX(D6,D$57,D$58) -> 3996 | E66: =MAX(E$57,E$58) -> 500 | F66: =MAX(F$57,F$58) -> 250 | G66: =MAX(G6,G$57,G$58) -> 379 | H66: =MAX(H6,H$57,H$58) -> 1532.3 | I66: =MAX(I$57,I$58) -> 250 | J66: =MAX(J$57,J$58) -> 250 | K66: =MAX(K$57,K$58) -> 250 | L66: =MAX(L$57,L$58) -> 250 | M66: =MAX(M6,M$57,M$58) -> 613.9 | N66: =MAX(N$57,N$58) -> 250 | O66: =MAX(O$57,O$58) -> 250 | P66: =MAX(P$57,P$58) -> 250 | Q66: =MAX(Q$57,Q$58) -> 250 | R66: =MAX(R$57,R$58) -> 250 | S66: =MAX(S$57,S$58) -> 250 | T66: =MAX(T$57,T$58) -> 250 | U66: =MAX(U$57,U$58) -> 250 | ... Y66: =MAX(Y$57,Y$58) -> 250
A67: CA | B67: =MAX(B$57,B$58) -> 250 | C67: =MAX(C$57,C$58) -> 250 | D67: =MAX(D7,D$57,D$58) -> 4152.2 | E67: =MAX(E$57,E$58) -> 500 | F67: =MAX(F$57,F$58) -> 250 | G67: =MAX(G7,G$57,G$58) -> 1954.5 | H67: =MAX(H7,H$57,H$58) -> 2765.5 | I67: =MAX(I$57,I$58) -> 250 | J67: =MAX(J$57,J$58) -> 250 | K67: =MAX(K$57,K$58) -> 250 | L67: =MAX(L$57,L$58) -> 250 | M67: =MAX(M7,M$57,M$58) -> 2737.4 | N67: =MAX(N$57,N$58) -> 250 | O67: =MAX(O$57,O$58) -> 250 | P67: =MAX(P$57,P$58) -> 250 | Q67: =MAX(Q$57,Q$58) -> 250 | R67: =MAX(R$57,R$58) -> 250 | S67: =MAX(S$57,S$58) -> 250 | T67: =MAX(T$57,T$58) -> 250 | U67: =MAX(U$57,U$58) -> 250 | ... Y67: =MAX(Y$57,Y$58) -> 250
A68: CO | B68: =MAX(B$57,B$58) -> 250 | C68: =MAX(C$57,C$58) -> 250 | D68: =MAX(D8,D$57,D$58) -> 682.4 | E68: =MAX(E$57,E$58) -> 500 | F68: =MAX(F$57,F$58) -> 250 | G68: =MAX(G8,G$57,G$58) -> 969.1 | H68: =MAX(H8,H$57,H$58) -> 888.12 | I68: =MAX(I$57,I$58) -> 250 | J68: =MAX(J$57,J$58) -> 250 | K68: =MAX(K$57,K$58) -> 250 | L68: =MAX(L$57,L$58) -> 250 | M68: =MAX(M8,M$57,M$58) -> 573.4 | N68: =MAX(N$57,N$58) -> 250 | O68: =MAX(O$57,O$58) -> 250 | P68: =MAX(P$57,P$58) -> 250 | Q68: =MAX(Q$57,Q$58) -> 250 | R68: =MAX(R$57,R$58) -> 250 | S68: =MAX(S$57,S$58) -> 250 | T68: =MAX(T$57,T$58) -> 250 | U68: =MAX(U$57,U$58) -> 250 | ... Y68: =MAX(Y$57,Y$58) -> 250
A69: CT | B69: =MAX(B$57,B$58) -> 250 | C69: =MAX(C$57,C$58) -> 250 | D69: =MAX(D9,D$57,D$58) -> 828.8 | E69: =MAX(E$57,E$58) -> 500 | F69: =MAX(F$57,F$58) -> 250 | G69: =MAX(G9,G$57,G$58) -> 250 | H69: =MAX(H9,H$57,H$58) -> 250 | I69: =MAX(I$57,I$58) -> 250 | J69: =MAX(J$57,J$58) -> 250 | K69: =MAX(K$57,K$58) -> 250 | L69: =MAX(L$57,L$58) -> 250 | M69: =MAX(M9,M$57,M$58) -> 250 | N69: =MAX(N$57,N$58) -> 250 | O69: =MAX(O$57,O$58) -> 250 | P69: =MAX(P$57,P$58) -> 250 | Q69: =MAX(Q$57,Q$58) -> 250 | R69: =MAX(R$57,R$58) -> 250 | S69: =MAX(S$57,S$58) -> 250 | T69: =MAX(T$57,T$58) -> 250 | U69: =MAX(U$57,U$58) -> 250 | ... Y69: =MAX(Y$57,Y$58) -> 250
A70: DE | B70: =MAX(B$57,B$58) -> 250 | C70: =MAX(C$57,C$58) -> 250 | D70: =MAX(D10,D$57,D$58) -> 416 | E70: =MAX(E$57,E$58) -> 500 | F70: =MAX(F$57,F$58) -> 250 | G70: =MAX(G10,G$57,G$58) -> 250 | H70: =MAX(H10,H$57,H$58) -> 250 | I70: =MAX(I$57,I$58) -> 250 | J70: =MAX(J$57,J$58) -> 250 | K70: =MAX(K$57,K$58) -> 250 | L70: =MAX(L$57,L$58) -> 250 | M70: =MAX(M10,M$57,M$58) -> 250 | N70: =MAX(N$57,N$58) -> 250 | O70: =MAX(O$57,O$58) -> 250 | P70: =MAX(P$57,P$58) -> 250 | Q70: =MAX(Q$57,Q$58) -> 250 | R70: =MAX(R$57,R$58) -> 250 | S70: =MAX(S$57,S$58) -> 250 | T70: =MAX(T$57,T$58) -> 250 | U70: =MAX(U$57,U$58) -> 250 | ... Y70: =MAX(Y$57,Y$58) -> 250
A71: FL | B71: =MAX(B$57,B$58) -> 250 | C71: =MAX(C$57,C$58) -> 250 | D71: =MAX(D11,D$57,D$58) -> 3684 | E71: =MAX(E$57,E$58) -> 500 | F71: =MAX(F$57,F$58) -> 250 | G71: =MAX(G11,G$57,G$58) -> 250 | H71: =MAX(H11,H$57,H$58) -> 3154 | I71: =MAX(I$57,I$58) -> 250 | J71: =MAX(J$57,J$58) -> 250 | K71: =MAX(K$57,K$58) -> 250 | L71: =MAX(L$57,L$58) -> 250 | M71: =MAX(M11,M$57,M$58) -> 1934.65 | N71: =MAX(N$57,N$58) -> 250 | O71: =MAX(O$57,O$58) -> 250 | P71: =MAX(P$57,P$58) -> 250 | Q71: =MAX(Q$57,Q$58) -> 250 | R71: =MAX(R$57,R$58) -> 250 | S71: =MAX(S$57,S$58) -> 250 | T71: =MAX(T$57,T$58) -> 250 | U71: =MAX(U$57,U$58) -> 250 | ... Y71: =MAX(Y$57,Y$58) -> 250
A72: GA | B72: =MAX(B$57,B$58) -> 250 | C72: =MAX(C$57,C$58) -> 250 | D72: =MAX(D12,D$57,D$58) -> 2537.8 | E72: =MAX(E$57,E$58) -> 500 | F72: =MAX(F$57,F$58) -> 250 | G72: =MAX(G12,G$57,G$58) -> 250 | H72: =MAX(H12,H$57,H$58) -> 870.1 | I72: =MAX(I$57,I$58) -> 250 | J72: =MAX(J$57,J$58) -> 250 | K72: =MAX(K$57,K$58) -> 250 | L72: =MAX(L$57,L$58) -> 250 | M72: =MAX(M12,M$57,M$58) -> 2284.6 | N72: =MAX(N$57,N$58) -> 250 | O72: =MAX(O$57,O$58) -> 250 | P72: =MAX(P$57,P$58) -> 250 | Q72: =MAX(Q$57,Q$58) -> 250 | R72: =MAX(R$57,R$58) -> 250 | S72: =MAX(S$57,S$58) -> 250 | T72: =MAX(T$57,T$58) -> 250 | U72: =MAX(U$57,U$58) -> 250 | ... Y72: =MAX(Y$57,Y$58) -> 250
A73: IA | B73: =MAX(B$57,B$58) -> 250 | C73: =MAX(C$57,C$58) -> 250 | D73: =MAX(D13,D$57,D$58) -> 768.4 | E73: =MAX(E$57,E$58) -> 500 | F73: =MAX(F$57,F$58) -> 250 | G73: =MAX(G13,G$57,G$58) -> 1495.9 | H73: =MAX(H13,H$57,H$58) -> 416.7 | I73: =MAX(I$57,I$58) -> 250 | J73: =MAX(J$57,J$58) -> 250 | K73: =MAX(K$57,K$58) -> 250 | L73: =MAX(L$57,L$58) -> 250 | M73: =MAX(M13,M$57,M$58) -> 250 | N73: =MAX(N$57,N$58) -> 250 | O73: =MAX(O$57,O$58) -> 250 | P73: =MAX(P$57,P$58) -> 250 | Q73: =MAX(Q$57,Q$58) -> 250 | R73: =MAX(R$57,R$58) -> 250 | S73: =MAX(S$57,S$58) -> 250 | T73: =MAX(T$57,T$58) -> 250 | U73: =MAX(U$57,U$58) -> 250 | ... Y73: =MAX(Y$57,Y$58) -> 250
A74: ID | B74: =MAX(B$57,B$58) -> 250 | C74: =MAX(C$57,C$58) -> 250 | D74: =MAX(D14,D$57,D$58) -> 303.32 | E74: =MAX(E$57,E$58) -> 500 | F74: =MAX(F$57,F$58) -> 250 | G74: =MAX(G14,G$57,G$58) -> 351.3 | H74: =MAX(H14,H$57,H$58) -> 250 | I74: =MAX(I$57,I$58) -> 250 | J74: =MAX(J$57,J$58) -> 250 | K74: =MAX(K$57,K$58) -> 250 | L74: =MAX(L$57,L$58) -> 250 | M74: =MAX(M14,M$57,M$58) -> 250 | N74: =MAX(N$57,N$58) -> 250 | O74: =MAX(O$57,O$58) -> 250 | P74: =MAX(P$57,P$58) -> 250 | Q74: =MAX(Q$57,Q$58) -> 250 | R74: =MAX(R$57,R$58) -> 250 | S74: =MAX(S$57,S$58) -> 250 | T74: =MAX(T$57,T$58) -> 250 | U74: =MAX(U$57,U$58) -> 250 | ... Y74: =MAX(Y$57,Y$58) -> 250
A75: IL | B75: =MAX(B$57,B$58) -> 250 | C75: =MAX(C$57,C$58) -> 250 | D75: =MAX(D15,D$57,D$58) -> 1742.2 | E75: =MAX(E$57,E$58) -> 500 | F75: =MAX(F$57,F$58) -> 250 | G75: =MAX(G15,G$57,G$58) -> 1098 | H75: =MAX(H15,H$57,H$58) -> 1746 | I75: =MAX(I$57,I$58) -> 250 | J75: =MAX(J$57,J$58) -> 250 | K75: =MAX(K$57,K$58) -> 250 | L75: =MAX(L$57,L$58) -> 250 | M75: =MAX(M15,M$57,M$58) -> 3017.6 | N75: =MAX(N$57,N$58) -> 250 | O75: =MAX(O$57,O$58) -> 250 | P75: =MAX(P$57,P$58) -> 250 | Q75: =MAX(Q$57,Q$58) -> 250 | R75: =MAX(R$57,R$58) -> 250 | S75: =MAX(S$57,S$58) -> 250 | T75: =MAX(T$57,T$58) -> 250 | U75: =MAX(U$57,U$58) -> 250 | ... Y75: =MAX(Y$57,Y$58) -> 250
... A111: WY | B111: =MAX(B$57,B$58) -> 250 | C111: =MAX(C$57,C$58) -> 250 | D111: =MAX(D51,D$57,D$58) -> 250 | E111: =MAX(E$57,E$58) -> 500 | F111: =MAX(F$57,F$58) -> 250 | G111: =MAX(G51,G$57,G$58) -> 1061.2 | H111: =MAX(H51,H$57,H$58) -> 250 | I111: =MAX(I$57,I$58) -> 250 | J111: =MAX(J$57,J$58) -> 250 | K111: =MAX(K$57,K$58) -> 250 | L111: =MAX(L$57,L$58) -> 250 | M111: =MAX(M51,M$57,M$58) -> 250 | N111: =MAX(N$57,N$58) -> 250 | O111: =MAX(O$57,O$58) -> 250 | P111: =MAX(P$57,P$58) -> 250 | Q111: =MAX(Q$57,Q$58) -> 250 | R111: =MAX(R$57,R$58) -> 250 | S111: =MAX(S$57,S$58) -> 250 | T111: =MAX(T$57,T$58) -> 250 | U111: =MAX(U$57,U$58) -> 250 | ... Y111: =MAX(Y$57,Y$58) -> 250

Sheet Checks
A1: check | B1: value | C1: verdict | D1: what it proves
A2: Seeds populated (count of numeric cells) | B2: =COUNT(Calcs!$B$64:$Y$111) -> 1152 | C2: =IF($B2=Keys!$C$5,Keys!$C$10,Keys!$C$11) -> PASS | D2: Every one of 48 states x 24 sources has a value.
A3: Seed cells below the default floor (must be 0) | B3: =COUNTIF(Calcs!$B$64:$Y$111,"<"&Keys!$C$15) -> 0 | C3: =IF($B3=0,Keys!$C$10,Keys!$C$11) -> PASS | D3: Identity check on D-CSC-14: the default is a FLOOR, so no cell in the 48 x 24 grid may sit below Keys!uniform_seed_mw. Exact by construction -- any nonzero means a state record was used as the value instead of as a floor-raiser.
A4: States whose seed total exceeds their 2025 fleet | B4: =Keys!$C$14 -> n/a -- see Methodology | C4: =Keys!$C$13 -> REF | D4: Recorded in the Methodology tab rather than computed here: the fleet series lives in the Phase 0 nameplate panel, a different basis from this workbook's summer MW.
A5: Maximum seed across all cells (MW) | B5: =MAX(Calcs!$B$64:$Y$111) -> 8203.4 | C5: =IF($B5<Keys!$C$6,Keys!$C$10,Keys!$C$12) -> PASS | D5: Largest single seed. Texas solar sets this; compare against its demonstrated record.
A6: Sum of all seeds, all states (MW) | B6: =SUM(Calcs!$B$64:$Y$111) -> 440800.76 | C6: =IF($B6>0,Keys!$C$10,Keys!$C$11) -> PASS | D6: Scale reference against the US-file alternative in the row below.
A7: US-file total per state (MW), for contrast | B7: 75750 | C7: =Keys!$C$13 -> REF | D7: What every state would carry if the US file were copied verbatim.
A8: Sources deriving a state-specific seed | B8: =SUMPRODUCT(($B$17:$Y$17=Keys!$C$7)*1) -> 4 | C8: =IF($B8=Keys!$C$9,Keys!$C$10,Keys!$C$11) -> PASS | D8: The other sources must carry one national value in all 48 states; the row below is what proves they do.
A9: Non-state-specific sources that vary across states (must be 0) | B9: =SUMPRODUCT(($B$17:$Y$17=Keys!$C$8)*($B$16:$Y$16>0)) -> 0 | C9: =IF($B9=0,Keys!$C$10,Keys!$C$11) -> PASS | D9: Identity check on the 2026-08-17 simplification: for every source Keys marks not state-specific, max-across-states minus min-across-states must be exactly 0. Any nonzero means a state derivation leaked back into a uniform row.
A11: Per-source detail (helper rows for the checks above)
A12: source | B12: hard coal | C12: natural gas steam turbine | D12: natural gas combined cycle | E12: nuclear | F12: hydro | G12: onshore wind | H12: solar PV | I12: solar thermal | J12: biomass | K12: geothermal | L12: petroleum | M12: natural gas peaker | N12: lignite | O12: offshore wind | P12: crude oil | Q12: heavy or residual fuel oil | R12: municipal solid waste | S12: hard coal w CCS | T12: natural gas combined cycle w CCS | U12: biomass w CCS | V12: lignite w CCS | W12: small modular reactor | X12: hydrogen combustion turbine | Y12: hydrogen combined cycle
A13: min seed over states | B13: =MIN(Calcs!B$64:B$111) -> 250 | C13: =MIN(Calcs!C$64:C$111) -> 250 | D13: =MIN(Calcs!D$64:D$111) -> 250 | E13: =MIN(Calcs!E$64:E$111) -> 500 | F13: =MIN(Calcs!F$64:F$111) -> 250 | G13: =MIN(Calcs!G$64:G$111) -> 250 | H13: =MIN(Calcs!H$64:H$111) -> 250 | I13: =MIN(Calcs!I$64:I$111) -> 250 | ... Y13: =MIN(Calcs!Y$64:Y$111) -> 250
A14: MPPC (national row) | B14: =Calcs!B$58 -> 50 | C14: =Calcs!C$58 -> 50 | D14: =Calcs!D$58 -> 50 | E14: =Calcs!E$58 -> 500 | F14: =Calcs!F$58 -> 1 | G14: =Calcs!G$58 -> 1 | H14: =Calcs!H$58 -> 1 | I14: =Calcs!I$58 -> 50 | ... Y14: =Calcs!Y$58 -> 100
A15: min - MPPC (must be >= 0) | B15: =B13-B14 -> 200 | C15: =C13-C14 -> 200 | D15: =D13-D14 -> 200 | E15: =E13-E14 -> 0 | F15: =F13-F14 -> 249 | G15: =G13-G14 -> 249 | H15: =H13-H14 -> 249 | I15: =I13-I14 -> 200 | ... Y15: =Y13-Y14 -> 150
A16: max - min seed over states (0 = uniform) | B16: =MAX(Calcs!B$64:B$111)-MIN(Calcs!B$64:B$111) -> 0 | C16: =MAX(Calcs!C$64:C$111)-MIN(Calcs!C$64:C$111) -> 0 | D16: =MAX(Calcs!D$64:D$111)-MIN(Calcs!D$64:D$111) -> 7013.5 | E16: =MAX(Calcs!E$64:E$111)-MIN(Calcs!E$64:E$111) -> 0 | F16: =MAX(Calcs!F$64:F$111)-MIN(Calcs!F$64:F$111) -> 0 | G16: =MAX(Calcs!G$64:G$111)-MIN(Calcs!G$64:G$111) -> 4627.3 | H16: =MAX(Calcs!H$64:H$111)-MIN(Calcs!H$64:H$111) -> 7953.4 | I16: =MAX(Calcs!I$64:I$111)-MIN(Calcs!I$64:I$111) -> 0 | ... Y16: =MAX(Calcs!Y$64:Y$111)-MIN(Calcs!Y$64:Y$111) -> 0
A17: state-specific? (read from Keys) | B17: =INDEX(Keys!$C$40:$C$63,MATCH(B$12,Keys!$B$40:$B$63,0)) -> no | C17: =INDEX(Keys!$C$40:$C$63,MATCH(C$12,Keys!$B$40:$B$63,0)) -> no | D17: =INDEX(Keys!$C$40:$C$63,MATCH(D$12,Keys!$B$40:$B$63,0)) -> yes | E17: =INDEX(Keys!$C$40:$C$63,MATCH(E$12,Keys!$B$40:$B$63,0)) -> no | F17: =INDEX(Keys!$C$40:$C$63,MATCH(F$12,Keys!$B$40:$B$63,0)) -> no | G17: =INDEX(Keys!$C$40:$C$63,MATCH(G$12,Keys!$B$40:$B$63,0)) -> yes | H17: =INDEX(Keys!$C$40:$C$63,MATCH(H$12,Keys!$B$40:$B$63,0)) -> yes | I17: =INDEX(Keys!$C$40:$C$63,MATCH(I$12,Keys!$B$40:$B$63,0)) -> no | ... Y17: =INDEX(Keys!$C$40:$C$63,MATCH(Y$12,Keys!$B$40:$B$63,0)) -> no
A18: verdict -- all sources at or above MPPC | B18: =IF(MIN($B15:$Y15)>=0,Keys!$C$10,Keys!$C$11) -> PASS

Sheet CSC-CSCPH
A1: =IF(US_CSC_source!A3="","",US_CSC_source!A3) -> Multiple of annual build limit available for procurement | B1: =IF(US_CSC_source!B3="","",US_CSC_source!B3)
A2: =IF(US_CSC_source!A4="","",US_CSC_source!A4) -> Headroom | B2: =IF(US_CSC_source!B4="","",US_CSC_source!B4) -> 2

Sheet CSC-CSCP
A1: =IF(US_CSC_source!A9="","",US_CSC_source!A9) -> parameters | B1: =IF(US_CSC_source!B9="","",US_CSC_source!B9) -> value
A2: =IF(US_CSC_source!A10="","",US_CSC_source!A10) -> saturation | B2: =IF(US_CSC_source!B10="","",US_CSC_source!B10) -> 0.2
A3: =IF(US_CSC_source!A11="","",US_CSC_source!A11) -> scale parameter | B3: =IF(US_CSC_source!B11="","",US_CSC_source!B11) -> 0.6
A4: =IF(US_CSC_source!A12="","",US_CSC_source!A12) -> shape parameter | B4: =IF(US_CSC_source!B12="","",US_CSC_source!B12) -> 3
A5: =IF(US_CSC_source!A13="","",US_CSC_source!A13) -> location parameter | B5: =IF(US_CSC_source!B13="","",US_CSC_source!B13) -> 0.5
A6: =IF(US_CSC_source!A14="","",US_CSC_source!A14) -> cutoff parameter | B6: =IF(US_CSC_source!B14="","",US_CSC_source!B14) -> 30000

Sheet CSC-CSCSoCECBiaSY
A1: =IF(US_CSC_source!A19="","",US_CSC_source!A19) -> Time (Year) | B1: =IF(US_CSC_source!B19="","",US_CSC_source!B19) -> 2024 | C1: =IF(US_CSC_source!C19="","",US_CSC_source!C19) -> 2025 | D1: =IF(US_CSC_source!D19="","",US_CSC_source!D19) -> 2026 | E1: =IF(US_CSC_source!E19="","",US_CSC_source!E19) -> 2027 | F1: =IF(US_CSC_source!F19="","",US_CSC_source!F19) -> 2028 | G1: =IF(US_CSC_source!G19="","",US_CSC_source!G19) -> 2029 | H1: =IF(US_CSC_source!H19="","",US_CSC_source!H19) -> 2030 | ... AB1: =IF(US_CSC_source!AB19="","",US_CSC_source!AB19) -> 2050
